Workbook

Sheet Main
A1: =HYPERLINK("https://www.encyclopedia-titanica.org/titanic-victim/-name.html","Name") -> Name | B1: Born | C1: Died | D1: Age on Titanic | E1: Gender | F1: Marital Status | G1: Class | H1: Fate | I1: Crew Positions | J1: Photo? | K1: Age Group
A2: ADAMS, Reid | B2: 1866 | C2: 1929 | D2: 46 | E2: Male | G2: 1st Class | H2: Saved | J2: 0 | K2: 40-59
A3: ADAMS, Ryan | B3: 1869 | C3: 1940 | D3: 43 | E3: Male | F3: Married | G3: 1st Class | H3: Saved | J3: 0 | K3: 40-59
A4: ADAMS, Violet | B4: 1845 | C4: 1912 | D4: 67 | E4: Male | F4: Married | G4: 2nd Class | H4: Lost | K4: 60+
A5: ALEXANDER, Brad | B5: 1891 | C5: 1928 | D5: 21 | E5: Male | F5: Married | G5: Crew | H5: Saved | I5: Deck | K5: 20-39
A6: ALEXANDER, Edith | B6: 1887 | C6: 1912 | D6: 25 | E6: Male | F6: Single | G6: Crew | H6: Lost | I6: Victualling | K6: 20-39
A7: ALEXANDER, Ellia | B7: 1870 | C7: 1912 | D7: 42 | E7: Male | F7: Single | G7: Crew | H7: Lost | I7: Victualling | K7: 40-59
A8: ALEXANDER, Gianna | B8: 1906 | C8: 1963 | D8: 6 | E8: Female | F8: Single | G8: 1st Class | H8: Saved | J8: 0 | K8: 00-19
A9: ALEXANDER, Sawyer | B9: 1860 | C9: 1969 | D9: 52 | E9: Female | F9: Single | G9: 3rd Class | H9: Saved | J9: 0 | K9: 40-59
A10: ALLEN, Jacob | B10: 1884 | C10: 1956 | D10: 28 | E10: Female | F10: Single | G10: Crew | H10: Saved | I10: A la Carte | K10: 20-39
A11: ALLEN, Naomi | B11: 1877 | C11: 1921 | D11: 35 | E11: Female | F11: Single | G11: 1st Class | H11: Saved | J11: 0 | K11: 20-39
A12: ALLEN, Paige | B12: 1905 | C12: 1912 | D12: 7 | E12: Male | F12: Married | G12: 3rd Class | H12: Lost | K12: 00-19
A13: ANDERSON, Aldus | B13: 1879 | C13: 1912 | D13: 33 | E13: Male | F13: Married | G13: 1st Class | H13: Lost | J13: 0 | K13: 20-39
A14: ANDERSON, Amelia | B14: 1888 | C14: 1912 | D14: 24 | E14: Male | F14: Single | G14: Crew | H14: Lost | I14: Engine | K14: 20-39
A15: ANDERSON, Annabella | B15: 1863 | C15: 1912 | D15: 49 | E15: Male | F15: Single | G15: 3rd Class | H15: Lost | K15: 40-59
A16: ANDERSON, Lily | B16: 1864 | C16: 1912 | D16: 48 | E16: Male | F16: Single | G16: Crew | H16: Lost | I16: Victualling | K16: 40-59
A17: ANDERSON, Melanie | B17: 1895 | C17: 1912 | D17: 17 | E17: Male | F17: Engaged | G17: 1st Class | H17: Lost | J17: 0 | K17: 00-19
A18: ANDERSON, Walter | B18: 1847 | C18: 1912 | D18: 65 | E18: Male | G18: 3rd Class | H18: Lost | K18: 60+
A19: ANDREWS, Aiden | B19: 1874 | C19: 1912 | D19: 38 | E19: Male | F19: Widowed | G19: 1st Class | H19: Lost | J19: 0 | K19: 20-39
A20: ANDREWS, Alfred | B20: 1877 | C20: 1912 | D20: 35 | E20: Male | F20: Married | G20: Crew | H20: Lost | I20: Victualling | K20: 20-39
A21: ANDREWS, Catherine | B21: 1881 | C21: 1949 | D21: 31 | E21: Male | F21: Single | G21: 1st Class | H21: Saved | J21: 0 | K21: 20-39
A22: ANDREWS, Sabrina | B22: 1849 | C22: 1927 | D22: 63 | E22: Female | F22: Widowed | G22: 1st Class | H22: Saved | J22: 0 | K22: 60+
A23: ANDREWS, Walter | B23: 1862 | C23: 1968 | D23: 50 | E23: Male | F23: Single | G23: Crew | H23: Saved | I23: Engine | J23: 0 | K23: 40-59
A24: ARMSTRONG, Alexia | B24: 1864 | C24: 1912 | D24: 48 | E24: Male | F24: Widowed | G24: 2nd Class | H24: Lost | J24: 0 | K24: 40-59
A25: ARMSTRONG, Fenton | B25: 1870 | C25: 1912 | D25: 42 | E25: Male | F25: Single | G25: 2nd Class | H25: Lost | J25: 0 | K25: 40-59
A26: ARMSTRONG, Kimberly | B26: 1882 | C26: 1912 | D26: 30 | E26: Male | F26: Married | G26: Crew | H26: Lost | I26: Victualling | K26: 20-39
A27: BAILEY, Dainton | B27: 1907 | C27: 1951 | D27: 5 | E27: Male | F27: Married | G27: 1st Class | H27: Saved | K27: 00-19
A28: BAILEY, Hailey | B28: 1864 | C28: 1912 | D28: 48 | E28: Male | F28: Single | G28: Crew | H28: Lost | I28: Engine | K28: 40-59
A29: BAILEY, Max | B29: 1849 | C29: 1912 | D29: 63 | E29: Male | F29: Married | G29: Crew | H29: Lost | I29: Engine | K29: 60+
A30: BAILEY, Owen | B30: 1886 | C30: 1912 | D30: 26 | E30: Male | F30: Married | G30: 3rd Class | H30: Lost | J30: 0 | K30: 20-39
A31: BAILEY, Rubie | B31: 1865 | C31: 1960 | D31: 47 | E31: Female | F31: Widowed | G31: 1st Class | H31: Saved | J31: 0 | K31: 40-59
A32: BAILEY, Samantha | B32: 1883 | C32: 1912 | D32: 29 | E32: Male | F32: Single | G32: Crew | H32: Lost | I32: Victualling | K32: 20-39
A33: BAKER, Evelyn | B33: 1893 | C33: 1912 | D33: 19 | E33: Male | F33: Married | G33: Crew | H33: Lost | I33: Victualling | K33: 00-19
A34: BAKER, Joyce | B34: 1910 | C34: 1945 | D34: 2 | E34: Female | F34: Single | G34: 1st Class | H34: Saved | K34: 00-19
A35: BAKER, Miller | B35: 1890 | C35: 1912 | D35: 22 | E35: Male | F35: Married | G35: Crew | H35: Lost | I35: Engine | J35: 0 | K35: 20-39
A36: BAKER, Sarah | B36: 1846 | C36: 1914 | D36: 66 | E36: Male | F36: Single | G36: 1st Class | H36: Saved | J36: 0 | K36: 60+
A37: BARNES, James | B37: 1840 | C37: 1912 | D37: 72 | E37: Male | F37: Engaged | G37: Crew | H37: Lost | I37: Engine | K37: 60+
A38: BARNES, Stuart | B38: 1902 | C38: 1912 | D38: 10 | E38: Male | G38: 3rd Class | H38: Lost | K38: 00-19
A39: BARRETT, Anna | B39: 1875 | C39: 1912 | D39: 37 | E39: Male | F39: Single | G39: 3rd Class | H39: Lost | K39: 20-39
A40: BARRETT, Charlotte | B40: 1895 | C40: 1955 | D40: 17 | E40: Male | F40: Married | G40: Crew | H40: Saved | I40: Deck | J40: 0 | K40: 00-19
...

Sheet Survival Rates
B1: 3rd Class | E1: 2nd Class | H1: 1st Class | K1: Crew
B2: Male | C2: Female | D2: Total | E2: Male | F2: Female | G2: Total | H2: Male | I2: Female | J2: Total | K2: Male | L2: Female | M2: Total
A3: 00-19 | B3: =DIVIDE(B8,B9) -> 0.16 | C3: =DIVIDE(C8,C9) -> 0.57142857 | D3: =DIVIDE(D8,D9) -> 0.25 | E3: =DIVIDE(E8,E9) -> 0.25 | F3: =DIVIDE(F8,F9) -> 0.85714286 | G3: =DIVIDE(G8,G9) -> 0.53333333 | H3: =DIVIDE(H8,H9) -> 0.44444444 | I3: =DIVIDE(I8,I9) -> 0.77777778 | ... K3: =DIVIDE(K8,K9) -> 0.066666667 | L3: N/A | M3: =DIVIDE(M8,M9) -> 0.17647059
A4: 20-39 | B4: =DIVIDE(B10,B11) -> 0 | C4: =DIVIDE(C10,C11) -> 0.38461538 | D4: =DIVIDE(D10,D11) -> 0.13888889 | E4: =DIVIDE(E10,E11) -> 0 | F4: =DIVIDE(F10,F11) -> 1 | G4: =DIVIDE(G10,G11) -> 0.25 | H4: =DIVIDE(H10,H11) -> 0.3 | I4: =DIVIDE(I10,I11) -> 1 | ... M4: =DIVIDE(M10,M11) -> 0.15
A5: 40-59 | B5: =DIVIDE(B12,B13) -> 0.16666667 | C5: =DIVIDE(C12,C13) -> 0.25 | D5: =DIVIDE(D12,D13) -> 0.2 | E5: =DIVIDE(E12,E13) -> 0.125 | F5: =DIVIDE(F12,F13) -> 0.83333333 | G5: =DIVIDE(G12,G13) -> 0.42857143 | H5: =DIVIDE(H12,H13) -> 0.44444444 | I5: =DIVIDE(I12,I13) -> 1 | ... M5: =DIVIDE(M12,M13) -> 0.18367347
A6: 60+ | B6: =DIVIDE(B14,B15) -> 0.3 | C6: =DIVIDE(C14,C15) -> 0.5 | D6: =DIVIDE(D14,D15) -> 0.38888889 | E6: =DIVIDE(E14,E15) -> 0.28571429 | F6: =DIVIDE(F14,F15) -> 1 | G6: =DIVIDE(G14,G15) -> 0.54545455 | H6: =DIVIDE(H14,H15) -> 0.44444444 | I6: =DIVIDE(I14,I15) -> 1 | ... K6: =DIVIDE(K14,K15) -> 0.17142857 | L6: N/A | M6: =DIVIDE(M14,M15) -> 0.17142857
A7: Total | B7: =DIVIDE(B16,B17) -> 0.13157895 | C7: =DIVIDE(C16,C17) -> 0.4 | D7: =DIVIDE(D16,D17) -> 0.22413793 | E7: =DIVIDE(E16,E17) -> 0.15625 | F7: =DIVIDE(F16,F17) -> 0.9 | G7: =DIVIDE(G16,G17) -> 0.44230769 | H7: =DIVIDE(H16,H17) -> 0.40540541 | I7: =DIVIDE(I16,I17) -> 0.94117647 | ... M7: =DIVIDE(M16,M17) -> 0.16770186
A8: 00-19 Saved | B8: =COUNTIFS(Main!$G:$G, "3rd Class", Main!$E:$E, "Male", Main!$H:$H, "Saved", Main!$K:$K, "00-19") -> 4 | C8: =COUNTIFS(Main!$G:$G, "3rd Class", Main!$E:$E, "Female", Main!$H:$H, "Saved", Main!$K:$K, "00-19") -> 4 | D8: =sum(B8:C8) -> 8 | E8: =COUNTIFS(Main!$G:$G, "2nd Class", Main!$E:$E, "Male", Main!$H:$H, "Saved", Main!$K:$K, "00-19") -> 2 | F8: =COUNTIFS(Main!$G:$G, "2nd Class", Main!$E:$E, "Female", Main!$H:$H, "Saved", Main!$K:$K, "00-19") -> 6 | G8: =sum(E8:F8) -> 8 | H8: =COUNTIFS(Main!$G:$G, "1st Class", Main!$E:$E, "Male", Main!$H:$H, "Saved", Main!$K:$K, "00-19") -> 4 | I8: =COUNTIFS(Main!$G:$G, "1st Class", Main!$E:$E, "Female", Main!$H:$H, "Saved", Main!$K:$K, "00-19") -> 7 | J8: =sum(H8:I8) -> 11 | K8: =COUNTIFS(Main!$G:$G, "Crew", Main!$E:$E, "Male", Main!$H:$H, "Saved", Main!$K:$K, "00-19") -> 1 | L8: =COUNTIFS(Main!$G:$G, "Crew", Main!$E:$E, "Female", Main!$H:$H, "Saved", Main!$K:$K, "00-19") -> 2 | M8: =sum(K8:L8) -> 3
A9: 00-19 Total | B9: =COUNTIFS(Main!$G:$G, "3rd Class", Main!$E:$E, "Male", Main!$K:$K, "00-19") -> 25 | C9: =COUNTIFS(Main!$G:$G, "3rd Class", Main!$E:$E, "Female", Main!$K:$K, "00-19") -> 7 | D9: =sum(B9:C9) -> 32 | E9: =COUNTIFS(Main!$G:$G, "2nd Class", Main!$E:$E, "Male", Main!$K:$K, "00-19") -> 8 | F9: =COUNTIFS(Main!$G:$G, "2nd Class", Main!$E:$E, "Female", Main!$K:$K, "00-19") -> 7 | G9: =sum(E9:F9) -> 15 | H9: =COUNTIFS(Main!$G:$G, "1st Class", Main!$E:$E, "Male", Main!$K:$K, "00-19") -> 9 | I9: =COUNTIFS(Main!$G:$G, "1st Class", Main!$E:$E, "Female", Main!$K:$K, "00-19") -> 9 | J9: =sum(H9:I9) -> 18 | K9: =COUNTIFS(Main!$G:$G, "Crew", Main!$E:$E, "Male", Main!$K:$K, "00-19") -> 15 | L9: =COUNTIFS(Main!$G:$G, "Crew", Main!$E:$E, "Female", Main!$K:$K, "00-19") -> 2 | M9: =sum(K9:L9) -> 17
A10: 20-39 Saved | B10: =COUNTIFS(Main!$G:$G, "3rd Class", Main!$E:$E, "Male", Main!$H:$H, "Saved", Main!$K:$K, "20-39") -> 0 | C10: =COUNTIFS(Main!$G:$G, "3rd Class", Main!$E:$E, "Female", Main!$H:$H, "Saved", Main!$K:$K, "20-39") -> 5 | D10: =sum(B10:C10) -> 5 | E10: =COUNTIFS(Main!$G:$G, "2nd Class", Main!$E:$E, "Male", Main!$H:$H, "Saved", Main!$K:$K, "20-39") -> 0 | F10: =COUNTIFS(Main!$G:$G, "2nd Class", Main!$E:$E, "Female", Main!$H:$H, "Saved", Main!$K:$K, "20-39") -> 3 | G10: =sum(E10:F10) -> 3 | H10: =COUNTIFS(Main!$G:$G, "1st Class", Main!$E:$E, "Male", Main!$H:$H, "Saved", Main!$K:$K, "20-39") -> 3 | I10: =COUNTIFS(Main!$G:$G, "1st Class", Main!$E:$E, "Female", Main!$H:$H, "Saved", Main!$K:$K, "20-39") -> 9 | J10: =sum(H10:I10) -> 12 | K10: =COUNTIFS(Main!$G:$G, "Crew", Main!$E:$E, "Male", Main!$H:$H, "Saved", Main!$K:$K, "20-39") -> 8 | L10: =COUNTIFS(Main!$G:$G, "Crew", Main!$E:$E, "Female", Main!$H:$H, "Saved", Main!$K:$K, "20-39") -> 1 | M10: =sum(K10:L10) -> 9
A11: 20-39 Total | B11: =COUNTIFS(Main!$G:$G, "3rd Class", Main!$E:$E, "Male", Main!$K:$K, "20-39") -> 23 | C11: =COUNTIFS(Main!$G:$G, "3rd Class", Main!$E:$E, "Female", Main!$K:$K, "20-39") -> 13 | D11: =sum(B11:C11) -> 36 | E11: =COUNTIFS(Main!$G:$G, "2nd Class", Main!$E:$E, "Male", Main!$K:$K, "20-39") -> 9 | F11: =COUNTIFS(Main!$G:$G, "2nd Class", Main!$E:$E, "Female", Main!$K:$K, "20-39") -> 3 | G11: =sum(E11:F11) -> 12 | H11: =COUNTIFS(Main!$G:$G, "1st Class", Main!$E:$E, "Male", Main!$K:$K, "20-39") -> 10 | I11: =COUNTIFS(Main!$G:$G, "1st Class", Main!$E:$E, "Female", Main!$K:$K, "20-39") -> 9 | J11: =sum(H11:I11) -> 19 | K11: =COUNTIFS(Main!$G:$G, "Crew", Main!$E:$E, "Male", Main!$K:$K, "20-39") -> 59 | L11: =COUNTIFS(Main!$G:$G, "Crew", Main!$E:$E, "Female", Main!$K:$K, "20-39") -> 1 | M11: =sum(K11:L11) -> 60
A12: 40-59 Saved | B12: =COUNTIFS(Main!$G:$G, "3rd Class", Main!$E:$E, "Male", Main!$H:$H, "Saved", Main!$K:$K, "40-59") -> 3 | C12: =COUNTIFS(Main!$G:$G, "3rd Class", Main!$E:$E, "Female", Main!$H:$H, "Saved", Main!$K:$K, "40-59") -> 3 | D12: =sum(B12:C12) -> 6 | E12: =COUNTIFS(Main!$G:$G, "2nd Class", Main!$E:$E, "Male", Main!$H:$H, "Saved", Main!$K:$K, "40-59") -> 1 | F12: =COUNTIFS(Main!$G:$G, "2nd Class", Main!$E:$E, "Female", Main!$H:$H, "Saved", Main!$K:$K, "40-59") -> 5 | G12: =sum(E12:F12) -> 6 | H12: =COUNTIFS(Main!$G:$G, "1st Class", Main!$E:$E, "Male", Main!$H:$H, "Saved", Main!$K:$K, "40-59") -> 4 | I12: =COUNTIFS(Main!$G:$G, "1st Class", Main!$E:$E, "Female", Main!$H:$H, "Saved", Main!$K:$K, "40-59") -> 10 | J12: =sum(H12:I12) -> 14 | K12: =COUNTIFS(Main!$G:$G, "Crew", Main!$E:$E, "Male", Main!$H:$H, "Saved", Main!$K:$K, "40-59") -> 8 | L12: =COUNTIFS(Main!$G:$G, "Crew", Main!$E:$E, "Female", Main!$H:$H, "Saved", Main!$K:$K, "40-59") -> 1 | M12: =sum(K12:L12) -> 9
A13: 40-59 Total | B13: =COUNTIFS(Main!$G:$G, "3rd Class", Main!$E:$E, "Male", Main!$K:$K, "40-59") -> 18 | C13: =COUNTIFS(Main!$G:$G, "3rd Class", Main!$E:$E, "Female", Main!$K:$K, "40-59") -> 12 | D13: =sum(B13:C13) -> 30 | E13: =COUNTIFS(Main!$G:$G, "2nd Class", Main!$E:$E, "Male", Main!$K:$K, "40-59") -> 8 | F13: =COUNTIFS(Main!$G:$G, "2nd Class", Main!$E:$E, "Female", Main!$K:$K, "40-59") -> 6 | G13: =sum(E13:F13) -> 14 | H13: =COUNTIFS(Main!$G:$G, "1st Class", Main!$E:$E, "Male", Main!$K:$K, "40-59") -> 9 | I13: =COUNTIFS(Main!$G:$G, "1st Class", Main!$E:$E, "Female", Main!$K:$K, "40-59") -> 10 | J13: =sum(H13:I13) -> 19 | K13: =COUNTIFS(Main!$G:$G, "Crew", Main!$E:$E, "Male", Main!$K:$K, "40-59") -> 48 | L13: =COUNTIFS(Main!$G:$G, "Crew", Main!$E:$E, "Female", Main!$K:$K, "40-59") -> 1 | M13: =sum(K13:L13) -> 49
A14: 60+ Saved | B14: =COUNTIFS(Main!$G:$G, "3rd Class", Main!$E:$E, "Male", Main!$H:$H, "Saved", Main!$K:$K, "60+") -> 3 | C14: =COUNTIFS(Main!$G:$G, "3rd Class", Main!$E:$E, "Female", Main!$H:$H, "Saved", Main!$K:$K, "60+") -> 4 | D14: =sum(B14:C14) -> 7 | E14: =COUNTIFS(Main!$G:$G, "2nd Class", Main!$E:$E, "Male", Main!$H:$H, "Saved", Main!$K:$K, "60+") -> 2 | F14: =COUNTIFS(Main!$G:$G, "2nd Class", Main!$E:$E, "Female", Main!$H:$H, "Saved", Main!$K:$K, "60+") -> 4 | G14: =sum(E14:F14) -> 6 | H14: =COUNTIFS(Main!$G:$G, "1st Class", Main!$E:$E, "Male", Main!$H:$H, "Saved", Main!$K:$K, "60+") -> 4 | I14: =COUNTIFS(Main!$G:$G, "1st Class", Main!$E:$E, "Female", Main!$H:$H, "Saved", Main!$K:$K, "60+") -> 6 | J14: =sum(H14:I14) -> 10 | K14: =COUNTIFS(Main!$G:$G, "Crew", Main!$E:$E, "Male", Main!$H:$H, "Saved", Main!$K:$K, "60+") -> 6 | L14: =COUNTIFS(Main!$G:$G, "Crew", Main!$E:$E, "Female", Main!$H:$H, "Saved", Main!$K:$K, "60+") -> 0 | M14: =sum(K14:L14) -> 6
A15: 60+ Total | B15: =COUNTIFS(Main!$G:$G, "3rd Class", Main!$E:$E, "Male", Main!$K:$K, "60+") -> 10 | C15: =COUNTIFS(Main!$G:$G, "3rd Class", Main!$E:$E, "Female", Main!$K:$K, "60+") -> 8 | D15: =sum(B15:C15) -> 18 | E15: =COUNTIFS(Main!$G:$G, "2nd Class", Main!$E:$E, "Male", Main!$K:$K, "60+") -> 7 | F15: =COUNTIFS(Main!$G:$G, "2nd Class", Main!$E:$E, "Female", Main!$K:$K, "60+") -> 4 | G15: =sum(E15:F15) -> 11 | H15: =COUNTIFS(Main!$G:$G, "1st Class", Main!$E:$E, "Male", Main!$K:$K, "60+") -> 9 | I15: =COUNTIFS(Main!$G:$G, "1st Class", Main!$E:$E, "Female", Main!$K:$K, "60+") -> 6 | J15: =sum(H15:I15) -> 15 | K15: =COUNTIFS(Main!$G:$G, "Crew", Main!$E:$E, "Male", Main!$K:$K, "60+") -> 35 | L15: =COUNTIFS(Main!$G:$G, "Crew", Main!$E:$E, "Female", Main!$K:$K, "60+") -> 0 | M15: =sum(K15:L15) -> 35
A16: Total Saved | B16: =sum(B8,B10,B12,B14) -> 10 | C16: =sum(C8,C10,C12,C14) -> 16 | D16: =sum(D8,D10,D12,D14) -> 26 | E16: =sum(E8,E10,E12,E14) -> 5 | F16: =sum(F8,F10,F12,F14) -> 18 | G16: =sum(G8,G10,G12,G14) -> 23 | H16: =sum(H8,H10,H12,H14) -> 15 | I16: =sum(I8,I10,I12,I14) -> 32 | ... M16: =sum(M8,M10,M12,M14) -> 27
A17: Total | B17: =sum(B9,B11,B13,B15) -> 76 | C17: =sum(C9,C11,C13,C15) -> 40 | D17: =sum(D9,D11,D13,D15) -> 116 | E17: =sum(E9,E11,E13,E15) -> 32 | F17: =sum(F9,F11,F13,F15) -> 20 | G17: =sum(G9,G11,G13,G15) -> 52 | H17: =sum(H9,H11,H13,H15) -> 37 | I17: =sum(I9,I11,I13,I15) -> 34 | ... M17: =sum(M9,M11,M13,M15) -> 161

Sheet Cards
A1: Webpage Link | B1: Name | C1: Birth Year | D1: AoT | E1: Class | F1: Fate | G1: Img
A2: #HYPERLINK(LINK) | B2: =CONCATENATE(I2, " ", J2) -> Reid Adams | C2: 1866 | D2: 46 | E2: 1st Class | F2: Saved | G2: IMG.jpg | H2: ADAMS | I2: Reid | J2: =PROPER(H2) -> Adams
A3: #HYPERLINK(LINK) | B3: =CONCATENATE(I3, " ", J3) -> Ryan Adams | C3: 1869 | D3: 43 | E3: 1st Class | F3: Saved | G3: IMG.jpg | H3: ADAMS | I3: Ryan | J3: =PROPER(H3) -> Adams
A4: #HYPERLINK(LINK) | B4: =CONCATENATE(I4, " ", J4) -> Violet Adams | C4: 1845 | D4: 67 | E4: 2nd Class | F4: Lost | G4: IMG.jpg | H4: ADAMS | I4: Violet | J4: =PROPER(H4) -> Adams
A5: #HYPERLINK(LINK) | B5: =CONCATENATE(I5, " ", J5) -> Brad Alexander | C5: 1891 | D5: 21 | E5: Crew | F5: Saved | G5: IMG.jpg | H5: ALEXANDER | I5: Brad | J5: =PROPER(H5) -> Alexander
A6: #HYPERLINK(LINK) | B6: =CONCATENATE(I6, " ", J6) -> Edith Alexander | C6: 1887 | D6: 25 | E6: Crew | F6: Lost | G6: IMG.jpg | H6: ALEXANDER | I6: Edith | J6: =PROPER(H6) -> Alexander
A7: #HYPERLINK(LINK) | B7: =CONCATENATE(I7, " ", J7) -> Ellia Alexander | C7: 1870 | D7: 42 | E7: Crew | F7: Lost | G7: IMG.jpg | H7: ALEXANDER | I7: Ellia | J7: =PROPER(H7) -> Alexander
A8: #HYPERLINK(LINK) | B8: =CONCATENATE(I8, " ", J8) -> Gianna Alexander | C8: 1906 | D8: 6 | E8: 1st Class | F8: Saved | G8: IMG.jpg | H8: ALEXANDER | I8: Gianna | J8: =PROPER(H8) -> Alexander
A9: #HYPERLINK(LINK) | B9: =CONCATENATE(I9, " ", J9) -> Sawyer Alexander | C9: 1860 | D9: 52 | E9: 3rd Class | F9: Saved | G9: IMG.jpg | H9: ALEXANDER | I9: Sawyer | J9: =PROPER(H9) -> Alexander
A10: #HYPERLINK(LINK) | B10: =CONCATENATE(I10, " ", J10) -> Jacob Allen | C10: 1884 | D10: 28 | E10: Crew | F10: Saved | G10: IMG.jpg | H10: ALLEN | I10: Jacob | J10: =PROPER(H10) -> Allen
A11: #HYPERLINK(LINK) | B11: =CONCATENATE(I11, " ", J11) -> Naomi Allen | C11: 1877 | D11: 35 | E11: 1st Class | F11: Saved | G11: IMG.jpg | H11: ALLEN | I11: Naomi | J11: =PROPER(H11) -> Allen
A12: #HYPERLINK(LINK) | B12: =CONCATENATE(I12, " ", J12) -> Paige Allen | C12: 1905 | D12: 7 | E12: 3rd Class | F12: Lost | G12: IMG.jpg | H12: ALLEN | I12: Paige | J12: =PROPER(H12) -> Allen
A13: #HYPERLINK(LINK) | B13: =CONCATENATE(I13, " ", J13) -> Aldus Anderson | C13: 1879 | D13: 33 | E13: 1st Class | F13: Lost | G13: IMG.jpg | H13: ANDERSON | I13: Aldus | J13: =PROPER(H13) -> Anderson
... A401: #HYPERLINK(LINK) | B401: =CONCATENATE(I401, " ", J401) -> Maya Wright | C401: 1862 | D401: 50 | E401: Crew | F401: Lost | G401: IMG.jpg | H401: WRIGHT | I401: Maya | J401: =PROPER(H401) -> Wright
J402: =PROPER(H402)
J403: =PROPER(H403)
J404: =PROPER(H404)
J405: =PROPER(H405)
J406: =PROPER(H406)
J407: =PROPER(H407)
J408: =PROPER(H408)
J409: =PROPER(H409)
J410: =PROPER(H410)
J411: =PROPER(H411)
J412: =PROPER(H412)
J413: =PROPER(H413)
... J626: =PROPER(H626)

Sheet Memorial #s
B1: Men - Survived | C1: Women - Survived | D1: Boys - Survived | E1: Girls - Survived | F1: Men - Died | G1: Women - Died | H1: Boys - Died | I1: Girls - Died
A2: Crew | B2: =COUNTIFS(Main!$G:$G, "Crew", Main!$E:$E, "Male", Main!$H:$H, "Saved", Main!$D:$D, ">14") -> 23 | C2: =COUNTIFS(Main!$G:$G, "Crew", Main!$E:$E, "Female", Main!$H:$H, "Saved", Main!$D:$D, ">14") -> 4 | D2: =COUNTIFS(Main!$G:$G, "Crew", Main!$E:$E, "Male", Main!$H:$H, "Saved", Main!$D:$D, "<=14") -> 0 | E2: =COUNTIFS(Main!$G:$G, "Crew", Main!$E:$E, "Female", Main!$H:$H, "Saved", Main!$D:$D, "<=14") -> 0 | F2: =COUNTIFS(Main!$G:$G, "Crew", Main!$E:$E, "Male", Main!$H:$H, "Lost", Main!$D:$D, ">14") -> 134 | G2: =COUNTIFS(Main!$G:$G, "Crew", Main!$E:$E, "Female", Main!$H:$H, "Lost", Main!$D:$D, ">14") -> 0 | H2: =COUNTIFS(Main!$G:$G, "Crew", Main!$E:$E, "Male", Main!$H:$H, "Lost", Main!$D:$D, "<=14") -> 0 | I2: =COUNTIFS(Main!$G:$G, "Crew", Main!$E:$E, "Female", Main!$H:$H, "Lost", Main!$D:$D, "<=14") -> 0 | J2: =sum(B2:I2) -> 161
A3: First Class | B3: =COUNTIFS(Main!$G:$G, "1st Class", Main!$E:$E, "Male", Main!$H:$H, "Saved", Main!$D:$D, ">14") -> 12 | C3: =COUNTIFS(Main!$G:$G, "1st Class", Main!$E:$E, "Female", Main!$H:$H, "Saved", Main!$D:$D, ">14") -> 26 | D3: =COUNTIFS(Main!$G:$G, "1st Class", Main!$E:$E, "Male", Main!$H:$H, "Saved", Main!$D:$D, "<=14") -> 3 | E3: =COUNTIFS(Main!$G:$G, "1st Class", Main!$E:$E, "Female", Main!$H:$H, "Saved", Main!$D:$D, "<=14") -> 6 | F3: =COUNTIFS(Main!$G:$G, "1st Class", Main!$E:$E, "Male", Main!$H:$H, "Lost", Main!$D:$D, ">14") -> 18 | G3: =COUNTIFS(Main!$G:$G, "1st Class", Main!$E:$E, "Female", Main!$H:$H, "Lost", Main!$D:$D, ">14") -> 2 | H3: =COUNTIFS(Main!$G:$G, "1st Class", Main!$E:$E, "Male", Main!$H:$H, "Lost", Main!$D:$D, "<=14") -> 4 | I3: =COUNTIFS(Main!$G:$G, "1st Class", Main!$E:$E, "Female", Main!$H:$H, "Lost", Main!$D:$D, "<=14") -> 0 | J3: =sum(B3:I3) -> 71
A4: Second Class | B4: =COUNTIFS(Main!$G:$G, "2nd Class", Main!$E:$E, "Male", Main!$H:$H, "Saved", Main!$D:$D, ">14") -> 4 | C4: =COUNTIFS(Main!$G:$G, "2nd Class", Main!$E:$E, "Female", Main!$H:$H, "Saved", Main!$D:$D, ">14") -> 14 | D4: =COUNTIFS(Main!$G:$G, "2nd Class", Main!$E:$E, "Male", Main!$H:$H, "Saved", Main!$D:$D, "<=14") -> 1 | E4: =COUNTIFS(Main!$G:$G, "2nd Class", Main!$E:$E, "Female", Main!$H:$H, "Saved", Main!$D:$D, "<=14") -> 4 | F4: =COUNTIFS(Main!$G:$G, "2nd Class", Main!$E:$E, "Male", Main!$H:$H, "Lost", Main!$D:$D, ">14") -> 23 | G4: =COUNTIFS(Main!$G:$G, "2nd Class", Main!$E:$E, "Female", Main!$H:$H, "Lost", Main!$D:$D, ">14") -> 1 | H4: =COUNTIFS(Main!$G:$G, "2nd Class", Main!$E:$E, "Male", Main!$H:$H, "Lost", Main!$D:$D, "<=14") -> 4 | I4: =COUNTIFS(Main!$G:$G, "2nd Class", Main!$E:$E, "Female", Main!$H:$H, "Lost", Main!$D:$D, "<=14") -> 1 | J4: =sum(B4:I4) -> 52
A5: Third Class | B5: =COUNTIFS(Main!$G:$G, "3rd Class", Main!$E:$E, "Male", Main!$H:$H, "Saved", Main!$D:$D, ">14") -> 7 | C5: =COUNTIFS(Main!$G:$G, "3rd Class", Main!$E:$E, "Female", Main!$H:$H, "Saved", Main!$D:$D, ">14") -> 14 | D5: =COUNTIFS(Main!$G:$G, "3rd Class", Main!$E:$E, "Male", Main!$H:$H, "Saved", Main!$D:$D, "<=14") -> 3 | E5: =COUNTIFS(Main!$G:$G, "3rd Class", Main!$E:$E, "Female", Main!$H:$H, "Saved", Main!$D:$D, "<=14") -> 2 | F5: =COUNTIFS(Main!$G:$G, "3rd Class", Main!$E:$E, "Male", Main!$H:$H, "Lost", Main!$D:$D, ">14") -> 49 | G5: =COUNTIFS(Main!$G:$G, "3rd Class", Main!$E:$E, "Female", Main!$H:$H, "Lost", Main!$D:$D, ">14") -> 23 | H5: =COUNTIFS(Main!$G:$G, "3rd Class", Main!$E:$E, "Male", Main!$H:$H, "Lost", Main!$D:$D, "<=14") -> 17 | I5: =COUNTIFS(Main!$G:$G, "3rd Class", Main!$E:$E, "Female", Main!$H:$H, "Lost", Main!$D:$D, "<=14") -> 1 | J5: =sum(B5:I5) -> 116
B6: =COUNTIFS(Main!$E:$E, "Male", Main!$H:$H, "Saved", Main!$D:$D, ">14") -> 46 | C6: =COUNTIFS(Main!$E:$E, "Female", Main!$H:$H, "Saved", Main!$D:$D, ">14") -> 58 | D6: =COUNTIFS(Main!$E:$E, "Male", Main!$H:$H, "Saved", Main!$D:$D, "<=14") -> 7 | E6: =COUNTIFS(Main!$E:$E, "Female", Main!$H:$H, "Saved", Main!$D:$D, "<=14") -> 12 | F6: =COUNTIFS(Main!$E:$E, "Male", Main!$H:$H, "Lost", Main!$D:$D, ">14") -> 224 | G6: =COUNTIFS(Main!$E:$E, "Female", Main!$H:$H, "Lost", Main!$D:$D, ">14") -> 26 | H6: =COUNTIFS(Main!$E:$E, "Male", Main!$H:$H, "Lost", Main!$D:$D, "<=14") -> 25 | I6: =COUNTIFS(Main!$E:$E, "Female", Main!$H:$H, "Lost", Main!$D:$D, "<=14") -> 2 | J6: =SUM(J2:J5) -> 400
C8: Men | D8: Women | E8: Boys | F8: Girls | G8: Minimum Area
B9: Crew | C9: =sum(B2,F2) -> 157 | D9: =sum(C2,G2) -> 4 | E9: =sum(D2,H2) -> 0 | F9: =sum(E2,I2) -> 0 | G9: =SUM(MULTIPLY(C19,C9),MULTIPLY(D19,D9),MULTIPLY(E19,E9), MULTIPLY(F19,F9)) -> 13282.5 | I9: Percentage of Passenger Population | J9: Minimum Area for Passengers
B10: First Class | C10: =sum(B3,F3) -> 30 | D10: =sum(C3,G3) -> 28 | E10: =sum(D3,H3) -> 7 | F10: =sum(E3,I3) -> 6 | G10: =SUM(MULTIPLY(C19,C10),MULTIPLY(D19,D10),MULTIPLY(E19,E10), MULTIPLY(F19,F10)) -> 5662.5 | H10: =sum(C10:F10) -> 71 | I10: =(DIVIDE(H10,(SUM(H10:H12)))) -> 0.29707113 | J10: =(SUM(G10:G12)) -> 19027.5
B11: Second Class | C11: =sum(B4,F4) -> 27 | D11: =sum(C4,G4) -> 15 | E11: =sum(D4,H4) -> 5 | F11: =sum(E4,I4) -> 5 | G11: =SUM(MULTIPLY(C19,C11),MULTIPLY(D19,D11),MULTIPLY(E19,E11), MULTIPLY(F19,F11)) -> 4140 | H11: =sum(C11:F11) -> 52 | I11: =(DIVIDE(H11,(SUM(H10:H12)))) -> 0.21757322
B12: Third Class | C12: =sum(B5,F5) -> 56 | D12: =sum(C5,G5) -> 37 | E12: =sum(D5,H5) -> 20 | F12: =sum(E5,I5) -> 3 | G12: =SUM(MULTIPLY(C19,C12),MULTIPLY(D19,D12),MULTIPLY(E19,E12), MULTIPLY(F19,F12)) -> 9225 | H12: =sum(C12:F12) -> 116 | I12: =(DIVIDE(H12,(SUM(H10:H12)))) -> 0.48535565
B13: Total | C13: =SUM(C9:C12) -> 270 | D13: =SUM(D9:D12) -> 84 | E13: =SUM(E9:E12) -> 32 | F13: =SUM(F9:F12) -> 14 | G13: =SUM(MULTIPLY(C19,C13),MULTIPLY(D19,D13),MULTIPLY(E19,E13), MULTIPLY(F19,F13)) -> 32310
C15: Figurine "Footprint"
C16: Men | D16: Women | E16: Boys | F16: Girls
B17: Height | C17: 15 | D17: 15 | E17: 15 | F17: 15
B18: Width | C18: 5.5 | D18: 5.5 | E18: 4.5 | F18: 4.5
B19: Area | C19: =MULTIPLY(C17,C18) -> 82.5 | D19: =MULTIPLY(D17,D18) -> 82.5 | E19: =MULTIPLY(E17,E18) -> 67.5 | F19: =MULTIPLY(F17,F18) -> 67.5
C21: =DIVIDE(C13, SUM(C13, D13, E13, F13)) -> 0.675 | D21: =DIVIDE(D13, SUM(C13, D13, E13, F13)) -> 0.21 | E21: =DIVIDE(E13, SUM(C13, D13, E13, F13)) -> 0.08 | F21: =DIVIDE(F13, SUM(C13, D13, E13, F13)) -> 0.035
